[2023-04-23T16:29:03.763+0300] {taskinstance.py:1090} INFO - Dependencies all met for dep_context=non-requeueable deps ti=<TaskInstance: db_train.write_record manual__2023-04-23T13:28:57.014749+00:00 [queued]>
[2023-04-23T16:29:03.778+0300] {taskinstance.py:1090} INFO - Dependencies all met for dep_context=requeueable deps ti=<TaskInstance: db_train.write_record manual__2023-04-23T13:28:57.014749+00:00 [queued]>
[2023-04-23T16:29:03.778+0300] {taskinstance.py:1288} INFO - 
--------------------------------------------------------------------------------
[2023-04-23T16:29:03.778+0300] {taskinstance.py:1289} INFO - Starting attempt 1 of 5
[2023-04-23T16:29:03.778+0300] {taskinstance.py:1290} INFO - 
--------------------------------------------------------------------------------
[2023-04-23T16:29:03.797+0300] {taskinstance.py:1309} INFO - Executing <Task(MySqlOperator): write_record> on 2023-04-23 13:28:57.014749+00:00
[2023-04-23T16:29:03.817+0300] {standard_task_runner.py:55} INFO - Started process 31429 to run task
[2023-04-23T16:29:03.831+0300] {standard_task_runner.py:82} INFO - Running: ['airflow', 'tasks', 'run', 'db_train', 'write_record', 'manual__2023-04-23T13:28:57.014749+00:00', '--job-id', '28', '--raw', '--subdir', 'DAGS_FOLDER/train_db.py', '--cfg-path', '/tmp/tmplrhg16a3']
[2023-04-23T16:29:03.832+0300] {standard_task_runner.py:83} INFO - Job 28: Subtask write_record
[2023-04-23T16:29:04.029+0300] {task_command.py:389} INFO - Running <TaskInstance: db_train.write_record manual__2023-04-23T13:28:57.014749+00:00 [running]> on host vladimir-virtual-machine
[2023-04-23T16:29:04.060+0300] {abstractoperator.py:611} ERROR - Exception rendering Jinja template for task 'write_record', field 'sql'. Template: "\n            INSERT INTO popki\n            VALUES('{{ ds }}', '{{ dag.id }}')\n        "
Traceback (most recent call last):
  File "/home/vladimir/.local/lib/python3.10/site-packages/airflow/models/abstractoperator.py", line 603, in _do_render_template_fields
    rendered_content = self.render_template(
  File "/home/vladimir/.local/lib/python3.10/site-packages/airflow/models/abstractoperator.py", line 665, in render_template
    return render_template_to_string(template, context)
  File "/home/vladimir/.local/lib/python3.10/site-packages/airflow/utils/helpers.py", line 288, in render_template_to_string
    return render_template(template, cast(MutableMapping[str, Any], context), native=False)
  File "/home/vladimir/.local/lib/python3.10/site-packages/airflow/utils/helpers.py", line 283, in render_template
    return "".join(nodes)
  File "<template>", line 16, in root
  File "/home/vladimir/.local/lib/python3.10/site-packages/jinja2/runtime.py", line 852, in _fail_with_undefined_error
    raise self._undefined_exception(self._undefined_message)
jinja2.exceptions.UndefinedError: 'airflow.models.dag.DAG object' has no attribute 'id'
[2023-04-23T16:29:04.082+0300] {taskinstance.py:1776} ERROR - Task failed with exception
Traceback (most recent call last):
  File "/home/vladimir/.local/lib/python3.10/site-packages/airflow/models/taskinstance.py", line 1383, in _run_raw_task
    self._execute_task_with_callbacks(context, test_mode)
  File "/home/vladimir/.local/lib/python3.10/site-packages/airflow/models/taskinstance.py", line 1502, in _execute_task_with_callbacks
    task_orig = self.render_templates(context=context)
  File "/home/vladimir/.local/lib/python3.10/site-packages/airflow/models/taskinstance.py", line 2123, in render_templates
    original_task.render_template_fields(context)
  File "/home/vladimir/.local/lib/python3.10/site-packages/airflow/models/baseoperator.py", line 1179, in render_template_fields
    self._do_render_template_fields(self, self.template_fields, context, jinja_env, set())
  File "/home/vladimir/.local/lib/python3.10/site-packages/airflow/utils/session.py", line 75, in wrapper
    return func(*args, session=session, **kwargs)
  File "/home/vladimir/.local/lib/python3.10/site-packages/airflow/models/abstractoperator.py", line 603, in _do_render_template_fields
    rendered_content = self.render_template(
  File "/home/vladimir/.local/lib/python3.10/site-packages/airflow/models/abstractoperator.py", line 665, in render_template
    return render_template_to_string(template, context)
  File "/home/vladimir/.local/lib/python3.10/site-packages/airflow/utils/helpers.py", line 288, in render_template_to_string
    return render_template(template, cast(MutableMapping[str, Any], context), native=False)
  File "/home/vladimir/.local/lib/python3.10/site-packages/airflow/utils/helpers.py", line 283, in render_template
    return "".join(nodes)
  File "<template>", line 16, in root
  File "/home/vladimir/.local/lib/python3.10/site-packages/jinja2/runtime.py", line 852, in _fail_with_undefined_error
    raise self._undefined_exception(self._undefined_message)
jinja2.exceptions.UndefinedError: 'airflow.models.dag.DAG object' has no attribute 'id'
[2023-04-23T16:29:04.107+0300] {taskinstance.py:1327} INFO - Marking task as UP_FOR_RETRY. dag_id=db_train, task_id=write_record, execution_date=20230423T132857, start_date=20230423T132903, end_date=20230423T132904
[2023-04-23T16:29:04.117+0300] {standard_task_runner.py:100} ERROR - Failed to execute job 28 for task write_record ('airflow.models.dag.DAG object' has no attribute 'id'; 31429)
[2023-04-23T16:29:04.164+0300] {local_task_job.py:212} INFO - Task exited with return code 1
[2023-04-23T16:29:04.182+0300] {taskinstance.py:2596} INFO - 0 downstream tasks scheduled from follow-on schedule check
